<?xml version="1.0" encoding="utf-8"?>
<!-- This URDF was automatically created by SolidWorks to URDF Exporter! Originally created by Stephen Brawner (brawner@gmail.com)
     Commit Version: 1.6.0-4-g7f85cfe  Build Version: 1.6.7995.38578
     For more information, please see http://wiki.ros.org/sw_urdf_exporter -->
<robot
        name="xiaotian">
    <material name="black">
        <color rgba="0.0 0.0 0.0 1.0"/>
    </material>
    <material name="blue">
        <color rgba="0.0 0.0 0.8 1.0"/>
    </material>
    <material name="green">
        <color rgba="0.0 0.8 0.0 1.0"/>
    </material>
    <material name="grey">
        <color rgba="0.2 0.2 0.2 1.0"/>
    </material>
    <material name="silver">
        <color rgba="0.9137254901960784 0.9137254901960784 0.8470588235294118 1.0"/>
    </material>
    <material name="orange">
        <color rgba="1.0 0.4235294117647059 0.0392156862745098 1.0"/>
    </material>
    <material name="brown">
        <color rgba="0.8705882352941177 0.8117647058823529 0.7647058823529411 1.0"/>
    </material>
    <material name="red">
        <color rgba="0.8 0.0 0.0 1.0"/>
    </material>
    <material name="white">
        <color rgba="1.0 1.0 1.0 1.0"/>
    </material>
    <!-- ros_control plugin -->
    <gazebo>
        <plugin filename="liblegged_hw_sim.so" name="gazebo_ros_control">
            <robotNamespace>/</robotNamespace>
            <robotParam>legged_robot_description</robotParam>
            <robotSimType>legged_gazebo/LeggedHWSim</robotSimType>
        </plugin>
    </gazebo>
    <gazebo>
        <plugin filename="libgazebo_ros_p3d.so" name="p3d_base_controller">
            <alwaysOn>true</alwaysOn>
            <updateRate>1000.0</updateRate>
            <bodyName>base</bodyName>
            <topicName>ground_truth/state</topicName>
            <gaussianNoise>0</gaussianNoise>
            <frameName>world</frameName>
            <xyzOffsets>0 0 0</xyzOffsets>
            <rpyOffsets>0 0 0</rpyOffsets>
        </plugin>
    </gazebo>
    <link
            name="base">
        <inertial>
            <origin
                    xyz="-0.01444302 0.00030627 -0.00919854"
                    rpy="0 0 0"/>
            <mass
                    value="6.56790388"/>
        <inertia ixx="0.08481363" ixy="0.00044122" ixz="0.02126796"
               iyy="0.06448049" iyz="-0.00001440" izz="0.07447678"/>
        </inertial>
        <visual>
            <origin
                    xyz="0 0 0"
                    rpy="0 0 0"/>
            <geometry>
                <mesh
                        filename="package://legged_rl_description/meshes/xiaotian/base_link.STL"/>
            </geometry>
            <material
                    name="">
                <color
                        rgba="1 1 1 1"/>
            </material>
        </visual>
    <collision>
      <origin xyz="-0.04 0 0.09" rpy="0 0 0"/>
      <geometry>
        <box size="0.2 0.3 0.15"/>
      </geometry>
    </collision>
    </link>
    <joint name="unitree_imu_joint" type="fixed">
        <origin rpy="0. 0. 0." xyz="0. 0. 0."/>
        <parent link="base"/>
        <child link="unitree_imu"/>
    </joint>
    <!-- Imu link -->
    <link name="unitree_imu">
        <inertial>
            <mass value="0.01"/>
            <origin rpy="0 0 0" xyz="0 0 0"/>
            <inertia ixx="0.000001" ixy="0" ixz="0" iyy="0.000001" iyz="0" izz="0.000001"/>
        </inertial>
        <visual>
            <origin rpy="0 0 0" xyz="0 0 0"/>
            <geometry>
                <box size="0.015 0.015 0.004"/>
            </geometry>
        </visual>
        <material name="orange">
            <color rgba="255 108 10 255"/>
        </material>
    </link>
    <gazebo reference="unitree_imu">
        <material>Gazebo/Orange</material>
    </gazebo>
    <gazebo reference="unitree_imu_joint">
        <disableFixedJointLumping>true</disableFixedJointLumping>
    </gazebo>
    <link
            name="abad_L_Link">
        <inertial>
            <origin
                    xyz="-0.06847895 0.04744926 -0.00003937"
                    rpy="0 0 0"/>
            <mass
                    value="1.36321707"/>
            <inertia ixx="0.00124754" ixy="0.00018968" ixz="-0.00000161"
               iyy="0.00170318" iyz="0.00000147" izz="0.00150821" />
        </inertial>
        <visual>
            <origin
                    xyz="0 0 0"
                    rpy="0 0 0"/>
            <geometry>
                <mesh
                        filename="package://legged_rl_description/meshes/xiaotian/abad_left_link.STL"/>
            </geometry>
            <material
                    name="">
                <color
                        rgba="0.79216 0.81961 0.93333 1"/>
            </material>
        </visual>
    <collision>
      <origin xyz="-0.08 0 0" rpy="1.57 0 0" />
      <geometry>
        <cylinder length="0.15" radius="0.05"/>
      </geometry>
    </collision>
    </link>
    <joint
            name="abad_L_Joint"
            type="revolute">
        <origin
                xyz="0.0142 0.095 -0.08176"
                rpy="0 0 0"/>
        <parent
                link="base"/>
        <child
                link="abad_L_Link"/>
        <axis
                xyz="1 0 0"/>
        <limit
                lower="-0.38397"
                upper="1.39626"
                effort="80.0"
                velocity="20.0"/>
    </joint>
    <link
            name="hip_L_Link">
        <inertial>
            <origin
                    xyz="-0.02555967 -0.05066900 -0.03319070"
                    rpy="0 0 0"/>
            <mass
                    value="2.07876080"/>
      <inertia ixx="0.01218057" ixy="0.00158393" ixz="-0.00659095"
               iyy="0.01643105" iyz="0.00203191" izz="0.00753635"/>
        </inertial>
        <visual>
            <origin
                    xyz="0 0 0"
                    rpy="0 0 0"/>
            <geometry>
                <mesh
                        filename="package://legged_rl_description/meshes/xiaotian/hip_left_link.STL"/>
            </geometry>
            <material
                    name="">
                <color
                        rgba="0.79216 0.81961 0.93333 1"/>
            </material>
        </visual>
    <collision>
      <origin xyz="-0.10 -0.03 -0.14" rpy="0 0.53 0"/>
      <geometry>
        <cylinder length="0.22" radius="0.035"/>
      </geometry>
    </collision>
    </link>
    <joint
            name="hip_L_Joint"
            type="revolute">
        <origin
                xyz="-0.073 0.021 0"
                rpy="0 0 0"/>
        <parent
                link="abad_L_Link"/>
        <child
                link="hip_L_Link"/>
        <axis
                xyz="0 -1 0"/>
        <limit
                lower="-1.012291"
                upper="1.518436"
                effort="80.0"
                velocity="20.0"/>
    </joint>
    <link
            name="knee_L_Link">
        <inertial>
            <origin
                    xyz="0.05854607 -0.00008671 -0.09193953"
                    rpy="0 0 0"/>
            <mass
                    value="0.24827178"/>
      <inertia ixx="0.00213" ixy="-1.7948E-06" ixz="0.001337"
               iyy="0.0029981" iyz="2.661E-06" izz="0.00089395"/>
        </inertial>
        <visual>
            <origin
                    xyz="0 0 0"
                    rpy="0 0 0"/>
            <geometry>
                <mesh
                        filename="package://legged_rl_description/meshes/xiaotian/knee_left_link.STL"/>
            </geometry>
            <material
                    name="">
                <color
                        rgba="0.79216 0.81961 0.93333 1"/>
            </material>
        </visual>
    <collision>
      <origin xyz="0.078 0 -0.12" rpy="0 -0.55 0"/>
      <geometry>
        <cylinder length="0.26" radius="0.015"/>
      </geometry>
    </collision>
    </link>
    <joint
            name="knee_L_Joint"
            type="revolute">
        <origin
                xyz="-0.15 -0.021 -0.25981"
                rpy="0 0 0"/>
        <parent
                link="hip_L_Link"/>
        <child
                link="knee_L_Link"/>
        <axis
                xyz="0 -1 0"/>
        <limit
                lower="-0.872665"
                upper="1.39626"
                effort="80"
                velocity="20"/>
    </joint>
    <link
            name="foot_L_Link">
        <inertial>
            <origin
                    xyz="-0.00245810 0.00000000 0.03706242"
                    rpy="0 0 0"/>
            <mass
                    value="0.14047647"/>
            <inertia
                    ixx="0.00007326"
                    ixy="0.0"
                    ixz="0.00000519"
                    iyy="0.00007655"
                    iyz="0.0"
                    izz="0.00005623"/>
        </inertial>
        <visual>
            <origin
                    xyz="0 0 0"
                    rpy="0 0 0"/>
            <geometry>
                <mesh
                        filename="package://legged_rl_description/meshes/xiaotian/foot_left_link.STL"/>
            </geometry>
            <material
                    name="">
                <color
                        rgba="0.79216 0.81961 0.93333 1"/>
            </material>
        </visual>
    <collision>
      <origin xyz="0 0 0.035" rpy="0 0 0"/>
      <geometry>
        <sphere radius="0.035"/>
      </geometry>
    </collision>
    </link>
    <joint
            name="foot_L_Joint"
            type="fixed"
            dont_collapse="true">
        <origin
                xyz="0.15 0 -0.29066"
                rpy="0 0 0"/>
        <parent
                link="knee_L_Link"/>
        <child
                link="foot_L_Link"/>
        <axis
                xyz="0 0 0"/>
    </joint>
    <gazebo reference="foot_L_Joint">
        <disableFixedJointLumping>true</disableFixedJointLumping>
    </gazebo>
    <gazebo reference="hip_L_Link">
        <mu1>0.2</mu1>
        <mu2>0.2</mu2>
        <material>Gazebo/DarkGrey</material>
    </gazebo>
    <gazebo reference="knee_L_Link">
        <mu1>0.2</mu1>
        <mu2>0.2</mu2>
        <self_collide>0</self_collide>
        <material>Gazebo/DarkGrey</material>
        <kp value="1000000.0"/>
        <kd value="100.0"/>
    </gazebo>
    <gazebo reference="foot_L_Link">
        <mu1>2.0</mu1>
        <mu2>2.0</mu2>
        <self_collide>1</self_collide>
        <material>Gazebo/DarkGrey</material>
        <kp value="1000000.0"/>
        <kd value="100.0"/>
    </gazebo>
    <transmission name="abad_L_Joint_tran">
        <type>transmission_interface/SimpleTransmission</type>
        <joint name="abad_L_Joint">
            <hardwareInterface>hardware_interface/EffortJointInterface</hardwareInterface>
        </joint>
        <actuator name="abad_L_Joint_motor">
            <hardwareInterface>hardware_interface/EffortJointInterface</hardwareInterface>
            <mechanicalReduction>1</mechanicalReduction>
        </actuator>
    </transmission>
    <transmission name="hip_L_Joint_tran">
        <type>transmission_interface/SimpleTransmission</type>
        <joint name="hip_L_Joint">
            <hardwareInterface>hardware_interface/EffortJointInterface</hardwareInterface>
        </joint>
        <actuator name="hip_L_Joint_motor">
            <hardwareInterface>hardware_interface/EffortJointInterface</hardwareInterface>
            <mechanicalReduction>1</mechanicalReduction>
        </actuator>
    </transmission>
    <transmission name="knee_L_Joint_tran">
        <type>transmission_interface/SimpleTransmission</type>
        <joint name="knee_L_Joint">
            <hardwareInterface>hardware_interface/EffortJointInterface</hardwareInterface>
        </joint>
        <actuator name="knee_L_Joint_motor">
            <hardwareInterface>hardware_interface/EffortJointInterface</hardwareInterface>
            <mechanicalReduction>1</mechanicalReduction>
        </actuator>
    </transmission>

    <link
            name="abad_R_Link">
        <inertial>
            <origin
                    xyz="-0.06850082 -0.04744926 0.00010940"
                    rpy="0 0 0"/>
            <mass
                    value="1.36321707"/>
        <inertia ixx="0.00124657" ixy="-0.00019024" ixz="0.00000230"
               iyy="0.00170343" iyz="0.00000222" izz="0.00150943"/>
        </inertial>
        <visual>
            <origin
                    xyz="0 0 0"
                    rpy="0 0 0"/>
            <geometry>
                <mesh
                        filename="package://legged_rl_description/meshes/xiaotian/abad_right_link.STL"/>
            </geometry>
            <material
                    name="">
                <color
                        rgba="0.79216 0.81961 0.93333 1"/>
            </material>
        </visual>
    <collision>
      <origin xyz="-0.08 0 0" rpy="1.57 0 0" />
      <geometry>
        <cylinder length="0.15" radius="0.05"/>
      </geometry>
    </collision>
    </link>
    <joint
            name="abad_R_Joint"
            type="revolute">
        <origin
                xyz="0.0034 -0.095 -0.07976"
                rpy="0 0 0"/>
        <parent
                link="base"/>
        <child
                link="abad_R_Link"/>
        <axis
                xyz="-1 0 0"/>
        <limit effort="80.0" lower="-1.39626" upper="0.38397" velocity="20.0"/>
    </joint>
    <link
            name="hip_R_Link">
        <inertial>
          <origin rpy="0 0 0" xyz="-0.02566179 0.05066902 -0.03321693"/>
          <mass value="2.07875863"/>
          <inertia ixx="0.01217528" ixy="-0.00157669" ixz="-0.00657956"
                   iyy="0.01641645" iyz="-0.00203003" izz="0.00752704"/>
        </inertial>
        <visual>
            <origin
                    xyz="0 0 0"
                    rpy="0 0 0"/>
            <geometry>
                <mesh
                        filename="package://legged_rl_description/meshes/xiaotian/hip_right_link.STL"/>
            </geometry>
            <material
                    name="">
                <color
                        rgba="1 0.98039 0.6 1"/>
            </material>
        </visual>
    <collision>
      <origin xyz="-0.10 0.03 -0.14" rpy="0 0.53 0"/>
      <geometry>
        <cylinder length="0.22" radius="0.035"/>
      </geometry>
    </collision>
    </link>
    <joint
            name="hip_R_Joint"
            type="revolute">
        <origin
                xyz="-0.073 -0.021 0"
                rpy="0 0 0"/>
        <parent
                link="abad_R_Link"/>
        <child
                link="hip_R_Link"/>
        <axis
                xyz="0 -1 0"/>
        <limit
                lower="-1.518436"
                upper="1.012291"
                effort="80"
                velocity="20.0"/>
    </joint>
    <link
            name="knee_R_Link">
        <inertial>
          <origin rpy="0 0 0" xyz="0.058547 8.654E-05 -0.09194"/>
          <mass value="0.24827"/>
          <inertia ixx="0.0021301" ixy="1.7976E-06" ixz="0.001337"
                   iyy="0.0029982" iyz="-2.6645E-06" izz="0.00089395"/>
        </inertial>
        <visual>
            <origin
                    xyz="0 0 0"
                    rpy="0 0 0"/>
            <geometry>
                <mesh
                        filename="package://legged_rl_description/meshes/xiaotian/knee_right_link.STL"/>
            </geometry>
            <material
                    name="">
                <color
                        rgba="0.79216 0.81961 0.93333 1"/>
            </material>
        </visual>
    <collision>
      <origin xyz="0.078 0 -0.12" rpy="0 -0.55 0"/>
      <geometry>
        <cylinder length="0.26" radius="0.015"/>
      </geometry>
    </collision>
    </link>
    <joint
            name="knee_R_Joint"
            type="revolute">
        <origin rpy="0 0 0" xyz="-0.15 0.021 -0.25981"/>
        <parent
                link="hip_R_Link"/>
        <child
                link="knee_R_Link"/>
        <axis
                xyz="0 1 0"/>
        <limit effort="80" lower="-1.396263" upper="0.872665" velocity="50"/>
    </joint>
    <link
            name="foot_R_Link">
        <inertial>
            <origin
                    xyz="-0.00245810 0.00000000 0.03706242"
                    rpy="0 0 0"/>
            <mass
                    value="0.14047647"/>
            <inertia
                    ixx="0.00007326"
                    ixy="0.0"
                    ixz="0.00000519"
                    iyy="0.00007655"
                    iyz="0.0"
                    izz="0.00005623"/>
        </inertial>
        <visual>
            <origin
                    xyz="0 0 0"
                    rpy="0 0 0"/>
            <geometry>
                <mesh
                        filename="package://legged_rl_description/meshes/xiaotian/foot_right_link.STL"/>
            </geometry>
            <material
                    name="">
                <color
                        rgba="0.79216 0.81961 0.93333 1"/>
            </material>
        </visual>
    <collision>
      <origin xyz="0 0 0.035" rpy="0 0 0"/>
      <geometry>
        <sphere radius="0.035"/>
      </geometry>
    </collision>
    </link>
    <joint
            name="foot_R_Joint"
            type="fixed"
            dont_collapse="true">
        <origin
                xyz="0.15 0 -0.29066"
                rpy="0 0 0"/>
        <parent
                link="knee_R_Link"/>
        <child
                link="foot_R_Link"/>
        <axis
                xyz="0 0 0"/>
    </joint>
    <gazebo reference="foot_R_Joint">
        <disableFixedJointLumping>true</disableFixedJointLumping>
    </gazebo>
    <gazebo reference="hip_R_Link">
        <mu1>0.2</mu1>
        <mu2>0.2</mu2>
        <material>Gazebo/DarkGrey</material>
    </gazebo>
    <gazebo reference="knee_R_Link">
        <mu1>0.2</mu1>
        <mu2>0.2</mu2>
        <self_collide>0</self_collide>
        <material>Gazebo/DarkGrey</material>
        <kp value="1000000.0"/>
        <kd value="100.0"/>
    </gazebo>
    <gazebo reference="foot_R_Link">
        <mu1>2.0</mu1>
        <mu2>2.0</mu2>
        <self_collide>1</self_collide>
        <material>Gazebo/DarkGrey</material>
        <kp value="1000000.0"/>
        <kd value="100.0"/>
    </gazebo>
    <transmission name="abad_R_Joint_tran">
        <type>transmission_interface/SimpleTransmission</type>
        <joint name="abad_R_Joint">
            <hardwareInterface>hardware_interface/EffortJointInterface</hardwareInterface>
        </joint>
        <actuator name="abad_R_Joint_motor">
            <hardwareInterface>hardware_interface/EffortJointInterface</hardwareInterface>
            <mechanicalReduction>1</mechanicalReduction>
        </actuator>
    </transmission>
    <transmission name="hip_R_Joint_tran">
        <type>transmission_interface/SimpleTransmission</type>
        <joint name="hip_R_Joint">
            <hardwareInterface>hardware_interface/EffortJointInterface</hardwareInterface>
        </joint>
        <actuator name="hip_R_Joint_motor">
            <hardwareInterface>hardware_interface/EffortJointInterface</hardwareInterface>
            <mechanicalReduction>1</mechanicalReduction>
        </actuator>
    </transmission>
    <transmission name="knee_R_Joint_tran">
        <type>transmission_interface/SimpleTransmission</type>
        <joint name="knee_R_Joint">
            <hardwareInterface>hardware_interface/EffortJointInterface</hardwareInterface>
        </joint>
        <actuator name="knee_R_Joint_motor">
            <hardwareInterface>hardware_interface/EffortJointInterface</hardwareInterface>
            <mechanicalReduction>1</mechanicalReduction>
        </actuator>
    </transmission>
    <material name="d435F_aluminum">
        <color rgba="0.5 0.5 0.5 1"/>
    </material>
    <!-- camera body, with origin at bottom screw mount -->
    <joint name="d435F_joint" type="fixed">
        <origin rpy="0 0.69813 0" xyz="0.10 0 -0.10"/>
        <parent link="base"/>
        <child link="d435F_bottom_screw_frame"/>
    </joint>
    <link name="d435F_bottom_screw_frame"/>
    <joint name="d435F_link_joint" type="fixed">
        <origin rpy="0 0 0" xyz="0 0.0175 0.0125"/>
        <parent link="d435F_bottom_screw_frame"/>
        <child link="d435F_link"/>
    </joint>
    <link name="d435F_link">
        <visual>
            <origin rpy="1.5707963267948966 0 1.5707963267948966" xyz="0.0149 -0.0175 0"/>
            <geometry>
                <!-- <box size="${d435_cam_width} ${d435_cam_height} ${d435_cam_depth}"/> -->
                <mesh filename="package://realsense2_description/meshes/d435.dae"/>
                <!--<mesh filename="package://realsense2_description/meshes/d435/d435.dae" />-->
            </geometry>
            <material name="d435F_aluminum"/>
        </visual>
        <collision>
            <origin rpy="0 0 0" xyz="0 -0.0175 0"/>
            <geometry>
                <box size="0.02505 0.09 0.025"/>
            </geometry>
        </collision>
        <inertial>
            <!-- The following are not reliable values, and should not be used for modeling -->
            <mass value="0.072"/>
            <origin xyz="0 0 0"/>
            <inertia ixx="0.003881243" ixy="0.0" ixz="0.0" iyy="0.000498940" iyz="0.0" izz="0.003879257"/>
        </inertial>
    </link>
    <!-- camera depth joints and links -->
    <joint name="d435F_depth_joint" type="fixed">
        <origin rpy="0 0 0" xyz="0 0 0"/>
        <parent link="d435F_link"/>
        <child link="d435F_depth_frame"/>
    </joint>
    <link name="d435F_depth_frame"/>
    <joint name="d435F_depth_optical_joint" type="fixed">
        <origin rpy="-1.5707963267948966 0 -1.5707963267948966" xyz="0 0 0"/>
        <parent link="d435F_depth_frame"/>
        <child link="d435F_depth_optical_frame"/>
    </joint>
    <link name="d435F_depth_optical_frame"/>
    <!-- camera left IR joints and links -->
    <joint name="d435F_left_ir_joint" type="fixed">
        <origin rpy="0 0 0" xyz="0 0.0 0"/>
        <parent link="d435F_depth_frame"/>
        <child link="d435F_left_ir_frame"/>
    </joint>
    <link name="d435F_left_ir_frame"/>
    <joint name="d435F_left_ir_optical_joint" type="fixed">
        <origin rpy="-1.5707963267948966 0 -1.5707963267948966" xyz="0 0 0"/>
        <parent link="d435F_left_ir_frame"/>
        <child link="d435F_left_ir_optical_frame"/>
    </joint>
    <link name="d435F_left_ir_optical_frame"/>
    <!-- camera right IR joints and links -->
    <joint name="d435F_right_ir_joint" type="fixed">
        <origin rpy="0 0 0" xyz="0 -0.05 0"/>
        <parent link="d435F_depth_frame"/>
        <child link="d435F_right_ir_frame"/>
    </joint>
    <link name="d435F_right_ir_frame"/>
    <joint name="d435F_right_ir_optical_joint" type="fixed">
        <origin rpy="-1.5707963267948966 0 -1.5707963267948966" xyz="0 0 0"/>
        <parent link="d435F_right_ir_frame"/>
        <child link="d435F_right_ir_optical_frame"/>
    </joint>
    <link name="d435F_right_ir_optical_frame"/>
    <!-- camera color joints and links -->
    <joint name="d435F_color_joint" type="fixed">
        <origin rpy="0 0 0" xyz="0 0.015 0"/>
        <parent link="d435F_depth_frame"/>
        <child link="d435F_color_frame"/>
    </joint>
    <link name="d435F_color_frame"/>
    <joint name="d435F_color_optical_joint" type="fixed">
        <origin rpy="-1.5707963267948966 0 -1.5707963267948966" xyz="0 0 0"/>
        <parent link="d435F_color_frame"/>
        <child link="d435F_color_optical_frame"/>
    </joint>
    <link name="d435F_color_optical_frame"/>
    <gazebo reference="d435F_link">
        <self_collide>0</self_collide>
        <enable_wind>0</enable_wind>
        <kinematic>0</kinematic>
        <gravity>1</gravity>
        <!--<mu>1</mu>-->
        <mu2>1</mu2>
        <fdir1>0 0 0</fdir1>
        <!--<slip1>0</slip1>
                <slip2>0</slip2>-->
        <kp>1e+13</kp>
        <kd>1</kd>
        <!--<max_vel>0.01</max_vel>
                <min_depth>0</min_depth>-->
        <sensor name="d435Fcolor" type="camera">
            <camera name="d435F">
                <horizontal_fov>1.2112585008840648</horizontal_fov>
                <image>
                    <width>640</width>
                    <height>480</height>
                    <format>RGB_INT8</format>
                </image>
                <clip>
                    <near>0.1</near>
                    <far>100</far>
                </clip>
                <noise>
                    <type>gaussian</type>
                    <mean>0.0</mean>
                    <stddev>0.007</stddev>
                </noise>
            </camera>
            <always_on>0</always_on>
            <update_rate>30</update_rate>
            <visualize>0</visualize>
        </sensor>
        <sensor name="d435Fired1" type="camera">
            <camera name="d435F">
                <horizontal_fov>1.4870205226991688</horizontal_fov>
                <image>
                    <width>1280</width>
                    <height>720</height>
                    <format>L_INT8</format>
                </image>
                <clip>
                    <near>0.1</near>
                    <far>100</far>
                </clip>
                <noise>
                    <type>gaussian</type>
                    <mean>0.0</mean>
                    <stddev>0.05</stddev>
                </noise>
            </camera>
            <always_on>0</always_on>
            <update_rate>90</update_rate>
            <visualize>0</visualize>
        </sensor>
        <sensor name="d435Fired2" type="camera">
            <camera name="d435F">
                <horizontal_fov>1.4870205226991688</horizontal_fov>
                <image>
                    <width>1280</width>
                    <height>720</height>
                    <format>L_INT8</format>
                </image>
                <clip>
                    <near>0.1</near>
                    <far>100</far>
                </clip>
                <noise>
                    <type>gaussian</type>
                    <mean>0.0</mean>
                    <stddev>0.05</stddev>
                </noise>
            </camera>
            <always_on>0</always_on>
            <update_rate>90</update_rate>
            <visualize>0</visualize>
        </sensor>
        <sensor name="d435Fdepth" type="depth">
            <camera name="d435F">
                <horizontal_fov>1.5184364492350666</horizontal_fov>
                <image>
                    <width>106</width>
                    <height>60</height>
                </image>
                <clip>
                    <near>0.02</near>
                    <far>2.0</far>
                </clip>
                <noise>
                    <type>gaussian</type>
                    <mean>0.0</mean>
                    <stddev>0.100</stddev>
                </noise>
            </camera>
            <always_on>1</always_on>
            <update_rate>50</update_rate>
            <visualize>0</visualize>
        </sensor>
    </gazebo>
    <gazebo>
        <plugin filename="librealsense_gazebo_plugin.so" name="d435F">
            <prefix>d435F</prefix>
            <depthTopicName>aligned_depth_to_color/image_raw</depthTopicName>
            <depthCameraInfoTopicName>depth/camera_info</depthCameraInfoTopicName>
            <colorTopicName>color/image_raw</colorTopicName>
            <colorCameraInfoTopicName>color/camera_info</colorCameraInfoTopicName>
            <colorOpticalframeName>d435F_color_optical_frame</colorOpticalframeName>
            <depthOpticalframeName>d435F_depth_optical_frame</depthOpticalframeName>
            <rangeMinDepth>0.2</rangeMinDepth>
            <rangeMaxDepth>5.0</rangeMaxDepth>
            <pointCloud>True</pointCloud>
            <pointCloudTopicName>depth/color/points</pointCloudTopicName>
            <pointCloudCutoff>0.2</pointCloudCutoff>
            <pointCloudCutoffMax>5.0</pointCloudCutoffMax>
        </plugin>
    </gazebo>
</robot>